Workbook

Sheet Resumen Financiero
A1: LA TIENDA DEL GOCHO - RESUMEN FINANCIERO
A3: Métrica | B3: Valor | C3: Descripción
A4: Total Inversión (Egresos) | B4: =SUM(Compras!C4:C100) -> 646500 | C4: Todo el dinero invertido en mercancía y base.
A5: Total Cobrado (En Mano) | B5: =SUMIF(Ventas!G4:G99, "Pagado", Ventas!E4:E99) + SUMIF(Ventas!G4:G99, "Pendiente", Ventas!F4:F99) -> 331000 | C5: Dinero real en caja (Ventas pagadas + abonos de pendientes).
A6: Total Fiado (Por Cobrar) | B6: =SUMIF(Ventas!G4:G99, "Pendiente", Ventas!E4:E99) - SUMIF(Ventas!G4:G99, "Pendiente", Ventas!F4:F99) -> 189000 | C6: Dinero que te deben (Total a cobrar de pendientes menos sus abonos).
A7: Ventas Totales (Progreso) | B7: =B5+B6 -> 520000 | C7: Suma del valor total de todas las ventas.
A8: Ganancia Total Proyectada | B8: =SUMPRODUCT(Inventario!F4:F9, Inventario!H4:H9) -> 155833.33 | C8: Ganancia total acumulada según las unidades vendidas.
B12: 220
B13: 120

Sheet Deudores
A1: CONTROL DE CUENTAS POR COBRAR (DEUDORES)
A3: Cliente (Escribe el nombre) | B3: Deuda Bruta | C3: Total Abonado | D3: Saldo Pendiente | E3: Estado
A4: Camila | B4: =IF(A4="","",SUMIFS(Ventas!E:E, Ventas!B:B, A4, Ventas!G:G, "Pendiente")) -> 8000 | C4: =IF(A4="","",SUMIFS(Ventas!F:F, Ventas!B:B, A4, Ventas!G:G, "Pendiente")) -> 7000 | D4: =IF(A4="","",B4-C4) -> 1000 | E4: =IF(A4="","",IF(D4<=0,"Saldado ✅","Por Cobrar ⏳")) -> Por Cobrar ⏳
A5: Darling | B5: =IF(A5="","",SUMIFS(Ventas!E:E, Ventas!B:B, A5, Ventas!G:G, "Pendiente")) -> 14000 | C5: =IF(A5="","",SUMIFS(Ventas!F:F, Ventas!B:B, A5, Ventas!G:G, "Pendiente")) -> 6000 | D5: =IF(A5="","",B5-C5) -> 8000 | E5: =IF(A5="","",IF(D5<=0,"Saldado ✅","Por Cobrar ⏳")) -> Por Cobrar ⏳
A6: Fabian | B6: =IF(A6="","",SUMIFS(Ventas!E:E, Ventas!B:B, A6, Ventas!G:G, "Pendiente")) -> 0 | C6: =IF(A6="","",SUMIFS(Ventas!F:F, Ventas!B:B, A6, Ventas!G:G, "Pendiente")) -> 0 | D6: =IF(A6="","",B6-C6) -> 0 | E6: =IF(A6="","",IF(D6<=0,"Saldado ✅","Por Cobrar ⏳")) -> Saldado ✅
A7: Faysuri | B7: =IF(A7="","",SUMIFS(Ventas!E:E, Ventas!B:B, A7, Ventas!G:G, "Pendiente")) -> 8000 | C7: =IF(A7="","",SUMIFS(Ventas!F:F, Ventas!B:B, A7, Ventas!G:G, "Pendiente")) -> 0 | D7: =IF(A7="","",B7-C7) -> 8000 | E7: =IF(A7="","",IF(D7<=0,"Saldado ✅","Por Cobrar ⏳")) -> Por Cobrar ⏳
A8: Julian | B8: =IF(A8="","",SUMIFS(Ventas!E:E, Ventas!B:B, A8, Ventas!G:G, "Pendiente")) -> 18000 | C8: =IF(A8="","",SUMIFS(Ventas!F:F, Ventas!B:B, A8, Ventas!G:G, "Pendiente")) -> 0 | D8: =IF(A8="","",B8-C8) -> 18000 | E8: =IF(A8="","",IF(D8<=0,"Saldado ✅","Por Cobrar ⏳")) -> Por Cobrar ⏳ | H8: =SUM(D4:D26) -> 189000
A9: Michell | B9: =IF(A9="","",SUMIFS(Ventas!E:E, Ventas!B:B, A9, Ventas!G:G, "Pendiente")) -> 69000 | C9: =IF(A9="","",SUMIFS(Ventas!F:F, Ventas!B:B, A9, Ventas!G:G, "Pendiente")) -> 0 | D9: =IF(A9="","",B9-C9) -> 69000 | E9: =IF(A9="","",IF(D9<=0,"Saldado ✅","Por Cobrar ⏳")) -> Por Cobrar ⏳
A10: Motato | B10: =IF(A10="","",SUMIFS(Ventas!E:E, Ventas!B:B, A10, Ventas!G:G, "Pendiente")) -> 0 | C10: =IF(A10="","",SUMIFS(Ventas!F:F, Ventas!B:B, A10, Ventas!G:G, "Pendiente")) -> 0 | D10: =IF(A10="","",B10-C10) -> 0 | E10: =IF(A10="","",IF(D10<=0,"Saldado ✅","Por Cobrar ⏳")) -> Saldado ✅
A11: Nando | B11: =IF(A11="","",SUMIFS(Ventas!E:E, Ventas!B:B, A11, Ventas!G:G, "Pendiente")) -> 8000 | C11: =IF(A11="","",SUMIFS(Ventas!F:F, Ventas!B:B, A11, Ventas!G:G, "Pendiente")) -> 0 | D11: =IF(A11="","",B11-C11) -> 8000 | E11: =IF(A11="","",IF(D11<=0,"Saldado ✅","Por Cobrar ⏳")) -> Por Cobrar ⏳
A12: Nikolee | B12: =IF(A12="","",SUMIFS(Ventas!E:E, Ventas!B:B, A12, Ventas!G:G, "Pendiente")) -> 47000 | C12: =IF(A12="","",SUMIFS(Ventas!F:F, Ventas!B:B, A12, Ventas!G:G, "Pendiente")) -> 0 | D12: =IF(A12="","",B12-C12) -> 47000 | E12: =IF(A12="","",IF(D12<=0,"Saldado ✅","Por Cobrar ⏳")) -> Por Cobrar ⏳
A13: Santiago | B13: =IF(A13="","",SUMIFS(Ventas!E:E, Ventas!B:B, A13, Ventas!G:G, "Pendiente")) -> 0 | C13: =IF(A13="","",SUMIFS(Ventas!F:F, Ventas!B:B, A13, Ventas!G:G, "Pendiente")) -> 0 | D13: =IF(A13="","",B13-C13) -> 0 | E13: =IF(A13="","",IF(D13<=0,"Saldado ✅","Por Cobrar ⏳")) -> Saldado ✅
A14: Yerimar | B14: =IF(A14="","",SUMIFS(Ventas!E:E, Ventas!B:B, A14, Ventas!G:G, "Pendiente")) -> 8000 | C14: =IF(A14="","",SUMIFS(Ventas!F:F, Ventas!B:B, A14, Ventas!G:G, "Pendiente")) -> 0 | D14: =IF(A14="","",B14-C14) -> 8000 | E14: =IF(A14="","",IF(D14<=0,"Saldado ✅","Por Cobrar ⏳")) -> Por Cobrar ⏳
A15: luis | B15: =IF(A15="","",SUMIFS(Ventas!E:E, Ventas!B:B, A15, Ventas!G:G, "Pendiente")) -> 0 | C15: =IF(A15="","",SUMIFS(Ventas!F:F, Ventas!B:B, A15, Ventas!G:G, "Pendiente")) -> 0 | D15: =IF(A15="","",B15-C15) -> 0 | E15: =IF(A15="","",IF(D15<=0,"Saldado ✅","Por Cobrar ⏳")) -> Saldado ✅
A16: Jhoani | B16: =IF(A16="","",SUMIFS(Ventas!E:E, Ventas!B:B, A16, Ventas!G:G, "Pendiente")) -> 22000 | C16: =IF(A16="","",SUMIFS(Ventas!F:F, Ventas!B:B, A16, Ventas!G:G, "Pendiente")) -> 0 | D16: =IF(A16="","",B16-C16) -> 22000 | E16: =IF(A16="","",IF(D16<=0,"Saldado ✅","Por Cobrar ⏳")) -> Por Cobrar ⏳
B17: =IF(A17="","",SUMIFS(Ventas!E:E, Ventas!B:B, A17, Ventas!G:G, "Pendiente")) | C17: =IF(A17="","",SUMIFS(Ventas!F:F, Ventas!B:B, A17, Ventas!G:G, "Pendiente")) | D17: =IF(A17="","",B17-C17) | E17: =IF(A17="","",IF(D17<=0,"Saldado ✅","Por Cobrar ⏳"))
B18: =IF(A18="","",SUMIFS(Ventas!E:E, Ventas!B:B, A18, Ventas!G:G, "Pendiente")) | C18: =IF(A18="","",SUMIFS(Ventas!F:F, Ventas!B:B, A18, Ventas!G:G, "Pendiente")) | D18: =IF(A18="","",B18-C18) | E18: =IF(A18="","",IF(D18<=0,"Saldado ✅","Por Cobrar ⏳"))
B19: =IF(A19="","",SUMIFS(Ventas!E:E, Ventas!B:B, A19, Ventas!G:G, "Pendiente")) | C19: =IF(A19="","",SUMIFS(Ventas!F:F, Ventas!B:B, A19, Ventas!G:G, "Pendiente")) | D19: =IF(A19="","",B19-C19) | E19: =IF(A19="","",IF(D19<=0,"Saldado ✅","Por Cobrar ⏳"))
B20: =IF(A20="","",SUMIFS(Ventas!E:E, Ventas!B:B, A20, Ventas!G:G, "Pendiente")) | C20: =IF(A20="","",SUMIFS(Ventas!F:F, Ventas!B:B, A20, Ventas!G:G, "Pendiente")) | D20: =IF(A20="","",B20-C20) | E20: =IF(A20="","",IF(D20<=0,"Saldado ✅","Por Cobrar ⏳"))
B21: =IF(A21="","",SUMIFS(Ventas!E:E, Ventas!B:B, A21, Ventas!G:G, "Pendiente")) | C21: =IF(A21="","",SUMIFS(Ventas!F:F, Ventas!B:B, A21, Ventas!G:G, "Pendiente")) | D21: =IF(A21="","",B21-C21) | E21: =IF(A21="","",IF(D21<=0,"Saldado ✅","Por Cobrar ⏳"))
B22: =IF(A22="","",SUMIFS(Ventas!E:E, Ventas!B:B, A22, Ventas!G:G, "Pendiente")) | C22: =IF(A22="","",SUMIFS(Ventas!F:F, Ventas!B:B, A22, Ventas!G:G, "Pendiente")) | D22: =IF(A22="","",B22-C22) | E22: =IF(A22="","",IF(D22<=0,"Saldado ✅","Por Cobrar ⏳"))
B23: =IF(A23="","",SUMIFS(Ventas!E:E, Ventas!B:B, A23, Ventas!G:G, "Pendiente")) | C23: =IF(A23="","",SUMIFS(Ventas!F:F, Ventas!B:B, A23, Ventas!G:G, "Pendiente")) | D23: =IF(A23="","",B23-C23) | E23: =IF(A23="","",IF(D23<=0,"Saldado ✅","Por Cobrar ⏳"))
B24: =IF(A24="","",SUMIFS(Ventas!E:E, Ventas!B:B, A24, Ventas!G:G, "Pendiente")) | C24: =IF(A24="","",SUMIFS(Ventas!F:F, Ventas!B:B, A24, Ventas!G:G, "Pendiente")) | D24: =IF(A24="","",B24-C24) | E24: =IF(A24="","",IF(D24<=0,"Saldado ✅","Por Cobrar ⏳"))
B25: =IF(A25="","",SUMIFS(Ventas!E:E, Ventas!B:B, A25, Ventas!G:G, "Pendiente")) | C25: =IF(A25="","",SUMIFS(Ventas!F:F, Ventas!B:B, A25, Ventas!G:G, "Pendiente")) | D25: =IF(A25="","",B25-C25) | E25: =IF(A25="","",IF(D25<=0,"Saldado ✅","Por Cobrar ⏳"))
B26: =IF(A26="","",SUMIFS(Ventas!E:E, Ventas!B:B, A26, Ventas!G:G, "Pendiente")) | C26: =IF(A26="","",SUMIFS(Ventas!F:F, Ventas!B:B, A26, Ventas!G:G, "Pendiente")) | D26: =IF(A26="","",B26-C26) | E26: =IF(A26="","",IF(D26<=0,"Saldado ✅","Por Cobrar ⏳"))
B27: =IF(A27="","",SUMIFS(Ventas!E:E, Ventas!B:B, A27, Ventas!G:G, "Pendiente")) | C27: =IF(A27="","",SUMIFS(Ventas!F:F, Ventas!B:B, A27, Ventas!G:G, "Pendiente")) | D27: =IF(A27="","",B27-C27) | E27: =IF(A27="","",IF(D27<=0,"Saldado ✅","Por Cobrar ⏳"))
B28: =IF(A28="","",SUMIFS(Ventas!E:E, Ventas!B:B, A28, Ventas!G:G, "Pendiente")) | C28: =IF(A28="","",SUMIFS(Ventas!F:F, Ventas!B:B, A28, Ventas!G:G, "Pendiente")) | D28: =IF(A28="","",B28-C28) | E28: =IF(A28="","",IF(D28<=0,"Saldado ✅","Por Cobrar ⏳"))
... B49: =IF(A49="","",SUMIFS(Ventas!E:E, Ventas!B:B, A49, Ventas!G:G, "Pendiente")) | C49: =IF(A49="","",SUMIFS(Ventas!F:F, Ventas!B:B, A49, Ventas!G:G, "Pendiente")) | D49: =IF(A49="","",B49-C49) | E49: =IF(A49="","",IF(D49<=0,"Saldado ✅","Por Cobrar ⏳"))

Sheet Inventario
A1: CONTROL DE INVENTARIO AUTOMÁTICO Y COSTOS
A3: Producto | B3: Costo Lote | C3: Unds Lote | D3: Costo x Und | E3: Precio Venta | F3: Ganancia x Und | G3: Stock Inicial | H3: Vendidas | I3: Stock Actual
A4: Chocolates (Lote 1) | B4: 41000 | C4: 12 | D4: =B4/C4 -> 3416.6667 | E4: 4000 | F4: =E4-D4 -> 583.33333 | G4: 48 | H4: =SUMIF(Ventas!$C$4:$C$99, A4, Ventas!$D$4:$D$99) -> 48 | I4: =G4-H4 -> 0
A5: Chocolates (Lote 2) | B5: 36000 | C5: 12 | D5: =B5/C5 -> 3000 | E5: 4000 | F5: =E5-D5 -> 1000 | G5: 48 | H5: =SUMIF(Ventas!$C$4:$C$99, A5, Ventas!$D$4:$D$99) -> 7 | I5: =G5-H5 -> 41
A6: Galletas (Paquete) | B6: 6500 | C6: 1 | D6: =B6/C6 -> 6500 | E6: 10000 | F6: =E6-D6 -> 3500 | G6: 20 | H6: =SUMIF(Ventas!$C$4:$C$99, A6, Ventas!$D$4:$D$99) -> 17 | I6: =G6-H6 -> 3
A7: Mayonesa Mediana | B7: 62500 | C7: 12 | D7: =B7/C7 -> 5208.3333 | E7: 6000 | F7: =E7-D7 -> 791.66667 | G7: 12 | H7: =SUMIF(Ventas!$C$4:$C$99, A7, Ventas!$D$4:$D$99) + SUMIF(Ventas!$C$4:$C$99, "Combo Arepero (Mayo+Diab)", Ventas!$D$4:$D$99) -> 8 | I7: =G7-H7 -> 4
A8: Diablitos Grandes | B8: 80000 | C8: 12 | D8: =B8/C8 -> 6666.6667 | E8: 10000 | F8: =E8-D8 -> 3333.3333 | G8: 12 | H8: =SUMIF(Ventas!$C$4:$C$99, A8, Ventas!$D$4:$D$99) + SUMIF(Ventas!$C$4:$C$99, "Combo Arepero (Mayo+Diab)", Ventas!$D$4:$D$99) -> 9 | I8: =G8-H8 -> 3
A9: Combo Arepero (Mayo+Diab) | B9: 0 | C9: 1 | D9: =D7+D8 -> 11875 | E9: 15000 | F9: =E9-D9 -> 3125 | G9: 0 | H9: =SUMIF(Ventas!$C$4:$C$99, A9, Ventas!$D$4:$D$99) -> 8 | I9: -

Sheet Ventas
A1: REGISTRO DIARIO DE VENTAS
A3: Fecha | B3: Cliente | C3: Producto | D3: Cantidad | E3: Total Cobrar | F3: Abono | G3: Estado
A4: 10/06/2026 | B4: Mamá | C4: Chocolates (Lote 1) | D4: 2 | E4: 8000 | F4: 0 | G4: Pagado
A5: 10/06/2026 | B5: itza | C5: Chocolates (Lote 1) | D5: 2 | E5: 8000 | F5: 0 | G5: Pagado
A6: 10/06/2026 | B6: ender | C6: Chocolates (Lote 1) | D6: 6 | E6: 24000 | F6: 0 | G6: Pagado
A7: 10/06/2026 | B7: ender | C7: Galletas (Paquete) | D7: 1 | E7: 10000 | F7: 0 | G7: Pagado
A8: 10/06/2026 | B8: Emanuel | C8: Chocolates (Lote 1) | D8: 3 | E8: 12000 | F8: 0 | G8: Pagado
A9: 10/06/2026 | B9: faysuri | C9: Chocolates (Lote 1) | D9: 2 | E9: 8000 | F9: 0 | G9: Pendiente
A10: 10/06/2026 | B10: Yerimar | C10: Chocolates (Lote 1) | D10: 2 | E10: 8000 | F10: 0 | G10: Pendiente
A11: 10/06/2026 | B11: Michell | C11: Chocolates (Lote 1) | D11: 7 | E11: 28000 | F11: 0 | G11: Pendiente
A12: 10/06/2026 | B12: Michell | C12: Galletas (Paquete) | D12: 1 | E12: 10000 | F12: 0 | G12: Pendiente
A13: 10/06/2026 | B13: Manuel | C13: Chocolates (Lote 1) | D13: 2 | E13: 8000 | F13: 0 | G13: Pagado
A14: 10/06/2026 | B14: Darling | C14: Galletas (Paquete) | D14: 1 | E14: 10000 | F14: 6000 | G14: Pendiente
A15: 10/06/2026 | B15: Nando | C15: Chocolates (Lote 1) | D15: 2 | E15: 8000 | F15: 0 | G15: Pagado
... A37: 16/06/2026 | B37: angely | C37: Combo Arepero (Mayo+Diab) | D37: 1 | E37: 15000 | F37: 0 | G37: Pagado
B38: camila | C38: Chocolates (Lote 2) | D38: 2 | E38: =D38*IFERROR(VLOOKUP(C38, Inventario!$A$4:$E$9, 5, FALSE), 0) -> 8000 | F38: 7000 | G38: Pendiente
B39: gabriel | C39: Chocolates (Lote 2) | D39: 1 | E39: =D39*IFERROR(VLOOKUP(C39, Inventario!$A$4:$E$9, 5, FALSE), 0) -> 4000 | F39: 0 | G39: Pagado
B40: Alejandro | C40: Chocolates (Lote 2) | D40: 1 | E40: =D40*IFERROR(VLOOKUP(C40, Inventario!$A$4:$E$9, 5, FALSE), 0) -> 4000 | F40: 0 | G40: Pagado
B41: Nando | C41: Chocolates (Lote 2) | D41: 2 | E41: =D41*IFERROR(VLOOKUP(C41, Inventario!$A$4:$E$9, 5, FALSE), 0) -> 8000 | F41: 0 | G41: Pendiente
B42: fabian | C42: Chocolates (Lote 2) | D42: 1 | E42: =D42*IFERROR(VLOOKUP(C42, Inventario!$A$4:$E$9, 5, FALSE), 0) -> 4000 | F42: 0 | G42: Pagado
B43: luis | C43: Galletas (Paquete) | D43: 2 | E43: =D43*IFERROR(VLOOKUP(C43, Inventario!$A$4:$E$9, 5, FALSE), 0) -> 20000 | F43: 0 | G43: Pagado
B44: luis | C44: Diablitos Grandes | D44: 1 | E44: =D44*IFERROR(VLOOKUP(C44, Inventario!$A$4:$E$9, 5, FALSE), 0) -> 10000 | F44: 0 | G44: Pagado
B45: Nikolee | C45: Galletas (Paquete) | D45: 2 | E45: =D45*IFERROR(VLOOKUP(C45, Inventario!$A$4:$E$9, 5, FALSE), 0) -> 20000 | F45: 0 | G45: Pendiente
B46: Jhoani | C46: Galletas (Paquete) | D46: 1 | E46: =D46*IFERROR(VLOOKUP(C46, Inventario!$A$4:$E$9, 5, FALSE), 0) -> 10000 | F46: 0 | G46: Pendiente
B47: Jhoani | C47: Chocolates (Lote 1) | D47: 3 | E47: =D47*IFERROR(VLOOKUP(C47, Inventario!$A$4:$E$9, 5, FALSE), 0) -> 12000 | F47: 0 | G47: Pendiente
B48: Michell | C48: Chocolates (Lote 1) | D48: 4 | E48: =D48*IFERROR(VLOOKUP(C48, Inventario!$A$4:$E$9, 5, FALSE), 0) -> 16000 | F48: 0 | G48: Pendiente
B49: nikolee | C49: Chocolates (Lote 1) | D49: 3 | E49: =D49*IFERROR(VLOOKUP(C49, Inventario!$A$4:$E$9, 5, FALSE), 0) -> 12000 | F49: 0 | G49: Pendiente
B50: Pabon | C50: palitos | D50: 3 | E50: =D50*IFERROR(VLOOKUP(C50, Inventario!$A$4:$E$9, 5, FALSE), 0) -> 0 | F50: 0
B51: nikol negra | C51: palitos | D51: 1 | E51: =D51*IFERROR(VLOOKUP(C51, Inventario!$A$4:$E$9, 5, FALSE), 0) -> 0 | F51: 0
B52: nikol Yañez | C52: palitos | D52: 2 | E52: =D52*IFERROR(VLOOKUP(C52, Inventario!$A$4:$E$9, 5, FALSE), 0) -> 0 | F52: 0
E53: =D53*IFERROR(VLOOKUP(C53, Inventario!$A$4:$E$9, 5, FALSE), 0) -> 0 | F53: 0
E54: =D54*IFERROR(VLOOKUP(C54, Inventario!$A$4:$E$9, 5, FALSE), 0) -> 0 | F54: 0
E55: =D55*IFERROR(VLOOKUP(C55, Inventario!$A$4:$E$9, 5, FALSE), 0) -> 0 | F55: 0
E56: =D56*IFERROR(VLOOKUP(C56, Inventario!$A$4:$E$9, 5, FALSE), 0) -> 0 | F56: 0
E57: =D57*IFERROR(VLOOKUP(C57, Inventario!$A$4:$E$9, 5, FALSE), 0) -> 0 | F57: 0
E58: =D58*IFERROR(VLOOKUP(C58, Inventario!$A$4:$E$9, 5, FALSE), 0) -> 0 | F58: 0
E59: =D59*IFERROR(VLOOKUP(C59, Inventario!$A$4:$E$9, 5, FALSE), 0) -> 0 | F59: 0
E60: =D60*IFERROR(VLOOKUP(C60, Inventario!$A$4:$E$9, 5, FALSE), 0) -> 0 | F60: 0
E61: =D61*IFERROR(VLOOKUP(C61, Inventario!$A$4:$E$9, 5, FALSE), 0) -> 0 | F61: 0
E62: =D62*IFERROR(VLOOKUP(C62, Inventario!$A$4:$E$9, 5, FALSE), 0) -> 0 | F62: 0
...

Sheet Compras
A1: REGISTRO DE COMPRAS E INVERSIONES
A3: Fecha | B3: Descripción | C3: Monto
A4: 10/06/2026 | B4: Inversión Inicial | C4: 295000
A5: 14/06/2026 | B5: Compra Mayonesas | C5: 62500
A6: 14/06/2026 | B6: Compra Diablitos | C6: 80000
A7: 18/06/2026 | B7: Compra 4 cajas Chocolates Lote 2 | C7: 144000
B8: sambas | C8: 45000
B9: palitos | C9: 20000
